Workbook

Sheet FLUJO DE CAJA
C2: CREC ANUAL (%) | D2: 10
C3: CREC INFLACIÓN AÑO | D3: 8
A9: FLUJO DE CAJA PROYECTADO | O9: TOTAL AÑO 1 | P9: TOTAL AÑO 2 | Q9: TOTAL AÑO 3
B10: Mes 0 | C10: Mes 1 | D10: Mes 2 | E10: Mes 3 | F10: Mes 4 | G10: Mes 5 | H10: Mes 6 | I10: Mes 7 | J10: Mes 8 | K10: Mes 9 | L10: Mes 10 | M10: Mes 11 | N10: Mes 12
A11: Valor de inversión | C11: =+B40 -> 0 | D11: =+C40 -> 1602200 | E11: =+D40 -> 3204400 | F11: =+E40 -> 4806600 | G11: =+F40 -> 6408800 | H11: =+G40 -> 8011000 | I11: =+H40 -> 9613200 | J11: =+I40 -> 11215400 | ... N11: =+M40 -> 17624200
A12: INGRESOS
A13: VENTAS PRODUCTO 1 | C13: ='Proyeccion Ventas'!P5 -> 15200000 | D13: ='Proyeccion Ventas'!P6 -> 15200000 | E13: ='Proyeccion Ventas'!P7 -> 15200000 | F13: ='Proyeccion Ventas'!P8 -> 15200000 | G13: ='Proyeccion Ventas'!P9 -> 15200000 | H13: ='Proyeccion Ventas'!P10 -> 15200000 | I13: ='Proyeccion Ventas'!P11 -> 15200000 | J13: ='Proyeccion Ventas'!P12 -> 15200000 | K13: ='Proyeccion Ventas'!P13 -> 15200000 | L13: ='Proyeccion Ventas'!P14 -> 15200000 | M13: ='Proyeccion Ventas'!P15 -> 15200000 | N13: ='Proyeccion Ventas'!P16 -> 15200000 | O13: =SUM(C13:N13) -> 182400000 | P13: =O13*(1+$D$2/100) -> 2.0064e+08 | Q13: =P13*(1+$D$2/100) -> 2.20704e+08
O14: =SUM(C14:N14) -> 0 | P14: =O14*(1+$D$2/100) -> 0 | Q14: =P14*(1+$D$2/100) -> 0
A17: TOTAL INGRESOS | C17: =SUM(C13:C16)+C11 -> 15200000 | D17: =SUM(D13:D16)+D11 -> 16802200 | E17: =SUM(E13:E16)+E11 -> 18404400 | F17: =SUM(F13:F16)+F11 -> 20006600 | G17: =SUM(G13:G16)+G11 -> 21608800 | H17: =SUM(H13:H16)+H11 -> 23211000 | I17: =SUM(I13:I16)+I11 -> 24813200 | J17: =SUM(J13:J16)+J11 -> 26415400 | ... N17: =SUM(N13:N16)+N11 -> 32824200 | O17: =SUM(O13:O16) -> 182400000 | P17: =SUM(P13:P16) -> 2.0064e+08 | Q17: =SUM(Q13:Q16) -> 2.20704e+08
A19: EGRESOS
C20: Mes 1 | D20: Mes 2 | E20: Mes 3 | F20: Mes 4 | G20: Mes 5 | H20: Mes 6 | I20: Mes 7 | J20: Mes 8 | K20: Mes 9 | L20: Mes 10 | M20: Mes 11 | N20: Mes 12
A22: COSTO DE PRODUCCIÓN PRODUCTO 1 | C22: ='Costos Unitarios de producción'!H4 -> 2397800 | D22: ='Costos Unitarios de producción'!H5 -> 2397800 | E22: ='Costos Unitarios de producción'!H6 -> 2397800 | F22: ='Costos Unitarios de producción'!H7 -> 2397800 | G22: ='Costos Unitarios de producción'!H8 -> 2397800 | H22: ='Costos Unitarios de producción'!H9 -> 2397800 | I22: ='Costos Unitarios de producción'!H10 -> 2397800 | J22: ='Costos Unitarios de producción'!H11 -> 2397800 | K22: ='Costos Unitarios de producción'!H12 -> 2397800 | L22: ='Costos Unitarios de producción'!H13 -> 2397800 | M22: ='Costos Unitarios de producción'!H14 -> 2397800 | N22: ='Costos Unitarios de producción'!H15 -> 2397800 | O22: =SUM(C22:N22) -> 28773600 | P22: =O22*(1+$D$3/100) -> 31075488 | Q22: =P22*(1+$D$3/100) -> 33561527
O23: =SUM(C23:N23) -> 0 | P23: =O23*(1+$D$3/100) -> 0 | Q23: =P23*(1+$D$3/100) -> 0
A26: COSTOS INDIRECTOS DE PRODUCCIÓN | C26: ='Costos Indirectos Fabricacion'!B20 -> 0 | D26: =C26 -> 0 | E26: =D26 -> 0 | F26: =E26 -> 0 | G26: =F26 -> 0 | H26: =G26 -> 0 | I26: =H26 -> 0 | J26: =I26 -> 0 | K26: =J26 -> 0 | ... N26: =M26 -> 0 | O26: =SUM(C26:N26) -> 0 | P26: =O26*(1+$D$3/100) -> 0 | Q26: =P26*(1+$D$3/100) -> 0
A28: PRESUPUESTO GASTOS FIJOS | C28: ='Ppto gastos fijos'!B24 -> 10700000 | D28: =C28 -> 10700000 | E28: =D28 -> 10700000 | F28: =E28 -> 10700000 | G28: =F28 -> 10700000 | H28: =G28 -> 10700000 | I28: =H28 -> 10700000 | J28: =I28 -> 10700000 | K28: =J28 -> 10700000 | ... N28: =M28 -> 10700000 | O28: =SUM(C28:N28) -> 128400000 | P28: =O28*(1+$D$3/100) -> 138672000 | Q28: =P28*(1+$D$3/100) -> 149765760
A30: PRESUPUESTO GASTOS VARIABLES | C30: ='Ppto gastos variables'!B21 -> 500000 | D30: =C30 -> 500000 | E30: =D30 -> 500000 | F30: =E30 -> 500000 | G30: =F30 -> 500000 | H30: =G30 -> 500000 | I30: =H30 -> 500000 | J30: =I30 -> 500000 | K30: =J30 -> 500000 | ... N30: =M30 -> 500000 | O30: =SUM(C30:N30) -> 6000000 | P30: =O30*(1+$D$3/100) -> 6480000 | Q30: =P30*(1+$D$3/100) -> 6998400
A33: TOTAL DE INFRAESTRUCTURA | B33: =Infraestructura!D85 -> 16790000
A35: TOTAL DE COSTOS DE PUESTA EN MARCHA | B35: =Infraestructura!D96 -> 21730000
A39: TOTAL EGRESOS | B39: =B33+B35 -> 38520000 | C39: =SUM(C21:C38) -> 13597800 | D39: =SUM(D21:D38) -> 13597800 | E39: =SUM(E21:E38) -> 13597800 | F39: =SUM(F21:F38) -> 13597800 | G39: =SUM(G21:G38) -> 13597800 | H39: =SUM(H21:H38) -> 13597800 | I39: =SUM(I21:I38) -> 13597800 | J39: =SUM(J21:J38) -> 13597800 | ... N39: =SUM(N21:N38) -> 13597800 | O39: =SUM(O22:O38) -> 163173600 | P39: =SUM(P22:P30) -> 176227488 | Q39: =SUM(Q22:Q30) -> 1.9032569e+08
A40: Superavit / déficit | C40: =+C17-C39 -> 1602200 | D40: =+D17-D39 -> 3204400 | E40: =+E17-E39 -> 4806600 | F40: =+F17-F39 -> 6408800 | G40: =+G17-G39 -> 8011000 | H40: =+H17-H39 -> 9613200 | I40: =+I17-I39 -> 11215400 | J40: =+J17-J39 -> 12817600 | ... N40: =+N17-N39 -> 19226400
A42: Consolidado | B42: =B17-B39 -> -38520000 | C42: =C17-C39 -> 1602200 | D42: =D17-D39 -> 3204400 | E42: =E17-E39 -> 4806600 | F42: =F17-F39 -> 6408800 | G42: =G17-G39 -> 8011000 | H42: =H17-H39 -> 9613200 | I42: =I17-I39 -> 11215400 | ... O42: =O17-O39 -> 19226400
A43: Aportes de socios | B43: 0 | L43: TIR | M43: =IRR(N43:Q43) -> 0.47506882 | N43: =-B39 -> -38520000 | O43: =O17-O39 -> 19226400 | P43: =P17-P39 -> 24412512 | Q43: =Q17-Q39+(B39/5*2) -> 45786313
L44: VAN | M44: {=NPV(0.1,N43:Q43)} -> 30485554
A45: Saldo de Caja Inicial | B45: 0 | C45: =B46 -> -38520000 | D45: =C46 -> -36917800 | E45: =D46 -> -33713400 | F45: =E46 -> -28906800 | G45: =F46 -> -22498000 | H45: =G46 -> -14487000 | I45: =H46 -> -4873800 | J45: =I46 -> 6341600 | K45: =J46 -> 19159200
A46: Saldo en caja Final | B46: =B17-B39+B43 -> -38520000 | C46: =C45+C17-C39 -> -36917800 | D46: =D45+D17-D39 -> -33713400 | E46: =E45+E17-E39 -> -28906800 | F46: =F45+F17-F39 -> -22498000 | G46: =G45+G17-G39 -> -14487000 | H46: =H45+H17-H39 -> -4873800 | I46: =I45+I17-I39 -> 6341600 | J46: =J45+J17-J39 -> 19159200 | K46: =K45+K17-K39 -> 33579000 | L46: LA TASA DE DESCUENTO ES DEL 10%

Sheet Proyeccion Ventas
A1: Unidades | H1: Precios de venta | O1: Ingresos
B3: Producto 1 | C3: producto 2 | D3: Producto 3 | E3: Producto 4 | F3: Producto 5 | I3: =+B3 -> Producto 1 | J3: =+C3 -> producto 2 | K3: =+D3 -> Producto 3 | L3: =+E3 -> Producto 4 | M3: =+F3 -> Producto 5 | P3: =+I3 -> Producto 1 | Q3: =+J3 -> producto 2 | R3: =+K3 -> Producto 3 | S3: =+L3 -> Producto 4 | T3: =+M3 -> Producto 5
A4: Año 1 | H4: Año 1 | O4: Año 1
A5: Mes 1 | B5: 380 | C5: 3 | D5: 2 | H5: Mes 1 | I5: 40000 | J5: 70000 | K5: 100000 | O5: Mes 1 | P5: =+I5*B5 -> 15200000 | Q5: =+J5*C5 -> 210000 | R5: =+K5*D5 -> 200000 | S5: =+L5*E5 -> 0 | T5: =+M5*F5 -> 0
A6: Mes 2 | B6: 380 | C6: 3 | D6: 2 | H6: Mes 2 | I6: 40000 | J6: 70000 | K6: 100000 | O6: Mes 2 | P6: =+I6*B6 -> 15200000 | Q6: =+J6*C6 -> 210000 | R6: =+K6*D6 -> 200000 | S6: =+L6*E6 -> 0 | T6: =+M6*F6 -> 0
A7: Mes 3 | B7: 380 | C7: 3 | D7: 2 | H7: Mes 3 | I7: 40000 | J7: 70000 | K7: 100000 | O7: Mes 3 | P7: =+I7*B7 -> 15200000 | Q7: =+J7*C7 -> 210000 | R7: =+K7*D7 -> 200000 | S7: =+L7*E7 -> 0 | T7: =+M7*F7 -> 0
A8: Mes 4 | B8: 380 | C8: 3 | D8: 2 | H8: Mes 4 | I8: 40000 | J8: 70000 | K8: 100000 | O8: Mes 4 | P8: =+I8*B8 -> 15200000 | Q8: =+J8*C8 -> 210000 | R8: =+K8*D8 -> 200000 | S8: =+L8*E8 -> 0 | T8: =+M8*F8 -> 0
A9: Mes 5 | B9: 380 | C9: 3 | D9: 2 | H9: Mes 5 | I9: 40000 | J9: 70000 | K9: 100000 | O9: Mes 5 | P9: =+I9*B9 -> 15200000 | Q9: =+J9*C9 -> 210000 | R9: =+K9*D9 -> 200000 | S9: =+L9*E9 -> 0 | T9: =+M9*F9 -> 0
A10: Mes 6 | B10: 380 | C10: 3 | D10: 2 | H10: Mes 6 | I10: 40000 | J10: 70000 | K10: 100000 | O10: Mes 6 | P10: =+I10*B10 -> 15200000 | Q10: =+J10*C10 -> 210000 | R10: =+K10*D10 -> 200000 | S10: =+L10*E10 -> 0 | T10: =+M10*F10 -> 0
A11: Mes 7 | B11: 380 | C11: 3 | D11: 2 | H11: Mes 7 | I11: 40000 | J11: 70000 | K11: 100000 | O11: Mes 7 | P11: =+I11*B11 -> 15200000 | Q11: =+J11*C11 -> 210000 | R11: =+K11*D11 -> 200000 | S11: =+L11*E11 -> 0 | T11: =+M11*F11 -> 0
A12: Mes 8 | B12: 380 | C12: 3 | D12: 2 | H12: Mes 8 | I12: 40000 | J12: 70000 | K12: 100000 | O12: Mes 8 | P12: =+I12*B12 -> 15200000 | Q12: =+J12*C12 -> 210000 | R12: =+K12*D12 -> 200000 | S12: =+L12*E12 -> 0 | T12: =+M12*F12 -> 0
A13: Mes 9 | B13: 380 | C13: 3 | D13: 2 | H13: Mes 9 | I13: 40000 | J13: 70000 | K13: 100000 | O13: Mes 9 | P13: =+I13*B13 -> 15200000 | Q13: =+J13*C13 -> 210000 | R13: =+K13*D13 -> 200000 | S13: =+L13*E13 -> 0 | T13: =+M13*F13 -> 0
A14: Mes 10 | B14: 380 | C14: 3 | D14: 2 | H14: Mes 10 | I14: 40000 | J14: 70000 | K14: 100000 | O14: Mes 10 | P14: =+I14*B14 -> 15200000 | Q14: =+J14*C14 -> 210000 | R14: =+K14*D14 -> 200000 | S14: =+L14*E14 -> 0 | T14: =+M14*F14 -> 0
A15: Mes 11 | B15: 380 | C15: 3 | D15: 2 | H15: Mes 11 | I15: 40000 | J15: 70000 | K15: 100000 | O15: Mes 11 | P15: =+I15*B15 -> 15200000 | Q15: =+J15*C15 -> 210000 | R15: =+K15*D15 -> 200000 | S15: =+L15*E15 -> 0 | T15: =+M15*F15 -> 0
A16: Mes 12 | B16: 380 | C16: 3 | D16: 2 | H16: Mes 12 | I16: 40000 | J16: 70000 | K16: 100000 | O16: Mes 12 | P16: =+I16*B16 -> 15200000 | Q16: =+J16*C16 -> 210000 | R16: =+K16*D16 -> 200000 | S16: =+L16*E16 -> 0 | T16: =+M16*F16 -> 0
A17: Total | B17: =+SUM(B5:B16) -> 4560 | C17: =+SUM(C5:C16) -> 36 | D17: =+SUM(D5:D16) -> 24 | E17: =+SUM(E5:E16) -> 0 | F17: =+SUM(F5:F16) -> 0 | H17: Total | O17: Total | P17: =+SUM(P5:P16) -> 182400000 | Q17: =+SUM(Q5:Q16) -> 2520000 | R17: =+SUM(R5:R16) -> 2400000 | S17: =+SUM(S5:S16) -> 0 | T17: =+SUM(T5:T16) -> 0
A18: Año 2 | H18: Año 2 | O18: Año 2
A19: Mes 1 | H19: Mes 1 | I19: =+I16*1.05 -> 42000 | J19: =+J16*1.95 -> 136500 | K19: =+K16*1.95 -> 195000 | L19: =+L16*1.95 -> 0 | M19: =+M16*1.95 -> 0 | O19: Mes 1 | P19: =+I19*B19 -> 0 | Q19: =+J19*C19 -> 0 | R19: =+K19*D19 -> 0 | S19: =+L19*E19 -> 0 | T19: =+M19*F19 -> 0
A20: Mes 2 | H20: Mes 2 | I20: =+I19 -> 42000 | J20: =+J19 -> 136500 | K20: =+K19 -> 195000 | L20: =+L19 -> 0 | M20: =+M19 -> 0 | O20: Mes 2 | P20: =+I20*B20 -> 0 | Q20: =+J20*C20 -> 0 | R20: =+K20*D20 -> 0 | S20: =+L20*E20 -> 0 | T20: =+M20*F20 -> 0
A21: Mes 3 | H21: Mes 3 | I21: =+I20 -> 42000 | J21: =+J20 -> 136500 | K21: =+K20 -> 195000 | L21: =+L20 -> 0 | M21: =+M20 -> 0 | O21: Mes 3 | P21: =+I21*B21 -> 0 | Q21: =+J21*C21 -> 0 | R21: =+K21*D21 -> 0 | S21: =+L21*E21 -> 0 | T21: =+M21*F21 -> 0
A22: Mes 4 | H22: Mes 4 | I22: =+I21 -> 42000 | J22: =+J21 -> 136500 | K22: =+K21 -> 195000 | L22: =+L21 -> 0 | M22: =+M21 -> 0 | O22: Mes 4 | P22: =+I22*B22 -> 0 | Q22: =+J22*C22 -> 0 | R22: =+K22*D22 -> 0 | S22: =+L22*E22 -> 0 | T22: =+M22*F22 -> 0
A23: Mes 5 | H23: Mes 5 | I23: =+I22 -> 42000 | J23: =+J22 -> 136500 | K23: =+K22 -> 195000 | L23: =+L22 -> 0 | M23: =+M22 -> 0 | O23: Mes 5 | P23: =+I23*B23 -> 0 | Q23: =+J23*C23 -> 0 | R23: =+K23*D23 -> 0 | S23: =+L23*E23 -> 0 | T23: =+M23*F23 -> 0
A24: Mes 6 | H24: Mes 6 | I24: =+I23 -> 42000 | J24: =+J23 -> 136500 | K24: =+K23 -> 195000 | L24: =+L23 -> 0 | M24: =+M23 -> 0 | O24: Mes 6 | P24: =+I24*B24 -> 0 | Q24: =+J24*C24 -> 0 | R24: =+K24*D24 -> 0 | S24: =+L24*E24 -> 0 | T24: =+M24*F24 -> 0
A25: Mes 7 | H25: Mes 7 | I25: =+I24 -> 42000 | J25: =+J24 -> 136500 | K25: =+K24 -> 195000 | L25: =+L24 -> 0 | M25: =+M24 -> 0 | O25: Mes 7 | P25: =+I25*B25 -> 0 | Q25: =+J25*C25 -> 0 | R25: =+K25*D25 -> 0 | S25: =+L25*E25 -> 0 | T25: =+M25*F25 -> 0
A26: Mes 8 | H26: Mes 8 | I26: =+I25 -> 42000 | J26: =+J25 -> 136500 | K26: =+K25 -> 195000 | L26: =+L25 -> 0 | M26: =+M25 -> 0 | O26: Mes 8 | P26: =+I26*B26 -> 0 | Q26: =+J26*C26 -> 0 | R26: =+K26*D26 -> 0 | S26: =+L26*E26 -> 0 | T26: =+M26*F26 -> 0
A27: Mes 9 | H27: Mes 9 | I27: =+I26 -> 42000 | J27: =+J26 -> 136500 | K27: =+K26 -> 195000 | L27: =+L26 -> 0 | M27: =+M26 -> 0 | O27: Mes 9 | P27: =+I27*B27 -> 0 | Q27: =+J27*C27 -> 0 | R27: =+K27*D27 -> 0 | S27: =+L27*E27 -> 0 | T27: =+M27*F27 -> 0
A28: Mes 10 | H28: Mes 10 | I28: =+I27 -> 42000 | J28: =+J27 -> 136500 | K28: =+K27 -> 195000 | L28: =+L27 -> 0 | M28: =+M27 -> 0 | O28: Mes 10 | P28: =+I28*B28 -> 0 | Q28: =+J28*C28 -> 0 | R28: =+K28*D28 -> 0 | S28: =+L28*E28 -> 0 | T28: =+M28*F28 -> 0
A29: Mes 11 | H29: Mes 11 | I29: =+I28 -> 42000 | J29: =+J28 -> 136500 | K29: =+K28 -> 195000 | L29: =+L28 -> 0 | M29: =+M28 -> 0 | O29: Mes 11 | P29: =+I29*B29 -> 0 | Q29: =+J29*C29 -> 0 | R29: =+K29*D29 -> 0 | S29: =+L29*E29 -> 0 | T29: =+M29*F29 -> 0
A30: Mes 12 | H30: Mes 12 | I30: =+I29 -> 42000 | J30: =+J29 -> 136500 | K30: =+K29 -> 195000 | L30: =+L29 -> 0 | M30: =+M29 -> 0 | O30: Mes 12 | P30: =+I30*B30 -> 0 | Q30: =+J30*C30 -> 0 | R30: =+K30*D30 -> 0 | S30: =+L30*E30 -> 0 | T30: =+M30*F30 -> 0
A31: Total | B31: =+SUM(B19:B30) -> 0 | C31: =+SUM(C19:C30) -> 0 | F31: =+SUM(F19:F30) -> 0 | H31: Total | O31: Total | P31: =+SUM(P19:P30) -> 0 | Q31: =+SUM(Q19:Q30) -> 0 | R31: =+SUM(R19:R30) -> 0 | S31: =+SUM(S19:S30) -> 0 | T31: =+SUM(T19:T30) -> 0
A32: Año 3 | H32: Año 3 | O32: Año 3
A33: Mes 1 | H33: Mes 1 | I33: =+I30*1.05 -> 44100 | J33: =+J30*1.95 -> 266175 | K33: =+K30*1.95 -> 380250 | L33: =+L30*1.95 -> 0 | M33: =+M30*1.95 -> 0 | O33: Mes 1 | P33: =+I33*B33 -> 0 | Q33: =+J33*C33 -> 0 | R33: =+K33*D33 -> 0 | S33: =+L33*E33 -> 0 | T33: =+M33*F33 -> 0
A34: Mes 2 | H34: Mes 2 | I34: =+I33 -> 44100 | J34: =+J33 -> 266175 | K34: =+K33 -> 380250 | L34: =+L33 -> 0 | M34: =+M33 -> 0 | O34: Mes 2 | P34: =+I34*B34 -> 0 | Q34: =+J34*C34 -> 0 | R34: =+K34*D34 -> 0 | S34: =+L34*E34 -> 0 | T34: =+M34*F34 -> 0
A35: Mes 3 | H35: Mes 3 | I35: =+I34 -> 44100 | J35: =+J34 -> 266175 | K35: =+K34 -> 380250 | L35: =+L34 -> 0 | M35: =+M34 -> 0 | O35: Mes 3 | P35: =+I35*B35 -> 0 | Q35: =+J35*C35 -> 0 | R35: =+K35*D35 -> 0 | S35: =+L35*E35 -> 0 | T35: =+M35*F35 -> 0
A36: Mes 4 | H36: Mes 4 | I36: =+I35 -> 44100 | J36: =+J35 -> 266175 | K36: =+K35 -> 380250 | L36: =+L35 -> 0 | M36: =+M35 -> 0 | O36: Mes 4 | P36: =+I36*B36 -> 0 | Q36: =+J36*C36 -> 0 | R36: =+K36*D36 -> 0 | S36: =+L36*E36 -> 0 | T36: =+M36*F36 -> 0
A37: Mes 5 | H37: Mes 5 | I37: =+I36 -> 44100 | J37: =+J36 -> 266175 | K37: =+K36 -> 380250 | L37: =+L36 -> 0 | M37: =+M36 -> 0 | O37: Mes 5 | P37: =+I37*B37 -> 0 | Q37: =+J37*C37 -> 0 | R37: =+K37*D37 -> 0 | S37: =+L37*E37 -> 0 | T37: =+M37*F37 -> 0
A38: Mes 6 | H38: Mes 6 | I38: =+I37 -> 44100 | J38: =+J37 -> 266175 | K38: =+K37 -> 380250 | L38: =+L37 -> 0 | M38: =+M37 -> 0 | O38: Mes 6 | P38: =+I38*B38 -> 0 | Q38: =+J38*C38 -> 0 | R38: =+K38*D38 -> 0 | S38: =+L38*E38 -> 0 | T38: =+M38*F38 -> 0
A39: Mes 7 | H39: Mes 7 | I39: =+I38 -> 44100 | J39: =+J38 -> 266175 | K39: =+K38 -> 380250 | L39: =+L38 -> 0 | M39: =+M38 -> 0 | O39: Mes 7 | P39: =+I39*B39 -> 0 | Q39: =+J39*C39 -> 0 | R39: =+K39*D39 -> 0 | S39: =+L39*E39 -> 0 | T39: =+M39*F39 -> 0
A40: Mes 8 | H40: Mes 8 | I40: =+I39 -> 44100 | J40: =+J39 -> 266175 | K40: =+K39 -> 380250 | L40: =+L39 -> 0 | M40: =+M39 -> 0 | O40: Mes 8 | P40: =+I40*B40 -> 0 | Q40: =+J40*C40 -> 0 | R40: =+K40*D40 -> 0 | S40: =+L40*E40 -> 0 | T40: =+M40*F40 -> 0
A41: Mes 9 | H41: Mes 9 | I41: =+I40 -> 44100 | J41: =+J40 -> 266175 | K41: =+K40 -> 380250 | L41: =+L40 -> 0 | M41: =+M40 -> 0 | O41: Mes 9 | P41: =+I41*B41 -> 0 | Q41: =+J41*C41 -> 0 | R41: =+K41*D41 -> 0 | S41: =+L41*E41 -> 0 | T41: =+M41*F41 -> 0
...

Sheet Costos Unitarios de producción
B1: PRODUCTO 1
C2: Mensual | F2: Año 1 | I2: Año 2 | L2: Año 3 | O2: Año 4 | R2: Año 5
B3: Concepto | C3: Cantidad | D3: Valor Unitario | E3: Valor total | F3: Cant/mes | G3: Valor Unitario | H3: Valor total | I3: Cantidad | J3: Valor Unitario | K3: Valor total | L3: Cantidad | M3: Valor Unitario | N3: Valor total | O3: Cantidad | P3: Valor Unitario | Q3: Valor total | R3: Cantidad | S3: Valor Unitario | T3: Valor total
B4: servidor | C4: 1 | D4: 50000 | E4: =D4*C4 -> 50000 | F4: ='Proyeccion Ventas'!B5 -> 380 | G4: =$E$28 -> 6310 | H4: =+G4*F4 -> 2397800 | K4: =+J4*I4 -> 0 | N4: =+M4*L4 -> 0 | Q4: =+P4*O4 -> 0 | T4: =+S4*R4 -> 0
B5: Marketing | C5: 1 | D5: 50000 | E5: =D5*C5 -> 50000 | F5: ='Proyeccion Ventas'!B6 -> 380 | G5: =$E$28 -> 6310 | H5: =+G5*F5 -> 2397800 | K5: =+J5*I5 -> 0 | N5: =+M5*L5 -> 0 | Q5: =+P5*O5 -> 0 | T5: =+S5*R5 -> 0
B6: Internet | C6: 1 | D6: 50000 | E6: =D6*C6 -> 50000 | F6: ='Proyeccion Ventas'!B7 -> 380 | G6: =$E$28 -> 6310 | H6: =+G6*F6 -> 2397800 | K6: =+J6*I6 -> 0 | N6: =+M6*L6 -> 0 | Q6: =+P6*O6 -> 0 | T6: =+S6*R6 -> 0
B7: Dominio | C7: 1 | D7: 2000 | E7: =D7*C7 -> 2000 | F7: ='Proyeccion Ventas'!B8 -> 380 | G7: =$E$28 -> 6310 | H7: =+G7*F7 -> 2397800 | K7: =+J7*I7 -> 0 | N7: =+M7*L7 -> 0 | Q7: =+P7*O7 -> 0 | T7: =+S7*R7 -> 0
B8: Material de capacitación | C8: 1 | D8: 3000 | E8: =D8*C8 -> 3000 | F8: ='Proyeccion Ventas'!B9 -> 380 | G8: =$E$28 -> 6310 | H8: =+G8*F8 -> 2397800 | K8: =+J8*I8 -> 0 | N8: =+M8*L8 -> 0 | Q8: =+P8*O8 -> 0 | T8: =+S8*R8 -> 0
B9: mano de obra(mes) | C9: 1 | D9: 3000000 | E9: =D9*C9 -> 3000000 | F9: ='Proyeccion Ventas'!B10 -> 380 | G9: =$E$28 -> 6310 | H9: =+G9*F9 -> 2397800 | K9: =+J9*I9 -> 0 | N9: =+M9*L9 -> 0 | Q9: =+P9*O9 -> 0 | T9: =+S9*R9 -> 0
E10: =D10*C10 -> 0 | F10: ='Proyeccion Ventas'!B11 -> 380 | G10: =$E$28 -> 6310 | H10: =+G10*F10 -> 2397800 | K10: =+J10*I10 -> 0 | N10: =+M10*L10 -> 0 | Q10: =+P10*O10 -> 0 | T10: =+S10*R10 -> 0
E11: =D11*C11 -> 0 | F11: ='Proyeccion Ventas'!B12 -> 380 | G11: =$E$28 -> 6310 | H11: =+G11*F11 -> 2397800 | K11: =+J11*I11 -> 0 | N11: =+M11*L11 -> 0 | Q11: =+P11*O11 -> 0 | T11: =+S11*R11 -> 0
E12: =D12*C12 -> 0 | F12: ='Proyeccion Ventas'!B13 -> 380 | G12: =$E$28 -> 6310 | H12: =+G12*F12 -> 2397800 | K12: =+J12*I12 -> 0 | N12: =+M12*L12 -> 0 | Q12: =+P12*O12 -> 0 | T12: =+S12*R12 -> 0
E13: =D13*C13 -> 0 | F13: ='Proyeccion Ventas'!B14 -> 380 | G13: =$E$28 -> 6310 | H13: =+G13*F13 -> 2397800 | K13: =+J13*I13 -> 0 | N13: =+M13*L13 -> 0 | Q13: =+P13*O13 -> 0 | T13: =+S13*R13 -> 0
E14: =D14*C14 -> 0 | F14: ='Proyeccion Ventas'!B15 -> 380 | G14: =$E$28 -> 6310 | H14: =+G14*F14 -> 2397800 | K14: =+J14*I14 -> 0 | N14: =+M14*L14 -> 0 | Q14: =+P14*O14 -> 0 | T14: =+S14*R14 -> 0
E15: =D15*C15 -> 0 | F15: ='Proyeccion Ventas'!B16 -> 380 | G15: =$E$28 -> 6310 | H15: =+G15*F15 -> 2397800 | K15: =+J15*I15 -> 0 | N15: =+M15*L15 -> 0 | Q15: =+P15*O15 -> 0 | T15: =+S15*R15 -> 0
E16: =D16*C16 -> 0 | H16: =+G16*F16 -> 0 | K16: =+J16*I16 -> 0 | N16: =+M16*L16 -> 0 | Q16: =+P16*O16 -> 0 | T16: =+S16*R16 -> 0
E17: =D17*C17 -> 0 | H17: =+G17*F17 -> 0 | K17: =+J17*I17 -> 0 | N17: =+M17*L17 -> 0 | Q17: =+P17*O17 -> 0 | T17: =+S17*R17 -> 0
E18: =D18*C18 -> 0 | H18: =+G18*F18 -> 0 | K18: =+J18*I18 -> 0 | N18: =+M18*L18 -> 0 | Q18: =+P18*O18 -> 0 | T18: =+S18*R18 -> 0
E19: =D19*C19 -> 0 | H19: =+G19*F19 -> 0 | K19: =+J19*I19 -> 0 | N19: =+M19*L19 -> 0 | Q19: =+P19*O19 -> 0 | T19: =+S19*R19 -> 0
E20: =D20*C20 -> 0 | H20: =+G20*F20 -> 0 | K20: =+J20*I20 -> 0 | N20: =+M20*L20 -> 0 | Q20: =+P20*O20 -> 0 | T20: =+S20*R20 -> 0
E21: =D21*C21 -> 0 | H21: =+G21*F21 -> 0 | K21: =+J21*I21 -> 0 | N21: =+M21*L21 -> 0 | Q21: =+P21*O21 -> 0 | T21: =+S21*R21 -> 0
B22: Total | E22: =+SUM(E4:E21) -> 3155000 | H22: =SUM(H4:H21) -> 28773600 | K22: =SUM(K4:K21) -> 0 | N22: =SUM(N4:N21) -> 0 | Q22: =SUM(Q4:Q21) -> 0 | T22: =SUM(T4:T21) -> 0
B25: unidades por lote producción | E25: 500
B28: valor unitario de producción | E28: =E22/E25 -> 6310
B33: PRODUCTO 2
C34: Mensual | F34: Año 1 | I34: Año 2 | L34: Año 3 | O34: Año 4 | R34: Año 5
B35: Concepto | C35: Cantidad | D35: Valor Unitario | E35: Valor total | F35: Cant/mes | G35: Valor Unitario | H35: Valor total | I35: Cantidad | J35: Valor Unitario | K35: Valor total | L35: Cantidad | M35: Valor Unitario | N35: Valor total | O35: Cantidad | P35: Valor Unitario | Q35: Valor total | R35: Cantidad | S35: Valor Unitario | T35: Valor total
E36: =D36*C36 -> 0 | F36: ='Proyeccion Ventas'!C5 -> 3 | G36: =$E$60 -> #DIV/0! | H36: =+G36*F36 -> #DIV/0! | K36: =+J36*I36 -> 0 | N36: =+M36*L36 -> 0 | Q36: =+P36*O36 -> 0 | T36: =+S36*R36 -> 0
E37: =D37*C37 -> 0 | F37: ='Proyeccion Ventas'!C6 -> 3 | G37: =$E$60 -> #DIV/0! | H37: =+G37*F37 -> #DIV/0! | K37: =+J37*I37 -> 0 | N37: =+M37*L37 -> 0 | Q37: =+P37*O37 -> 0 | T37: =+S37*R37 -> 0
E38: =D38*C38 -> 0 | F38: ='Proyeccion Ventas'!C7 -> 3 | G38: =$E$60 -> #DIV/0! | H38: =+G38*F38 -> #DIV/0! | K38: =+J38*I38 -> 0 | N38: =+M38*L38 -> 0 | Q38: =+P38*O38 -> 0 | T38: =+S38*R38 -> 0
E39: =D39*C39 -> 0 | F39: ='Proyeccion Ventas'!C8 -> 3 | G39: =$E$60 -> #DIV/0! | H39: =+G39*F39 -> #DIV/0! | K39: =+J39*I39 -> 0 | N39: =+M39*L39 -> 0 | Q39: =+P39*O39 -> 0 | T39: =+S39*R39 -> 0
E40: =D40*C40 -> 0 | F40: ='Proyeccion Ventas'!C9 -> 3 | G40: =$E$60 -> #DIV/0! | H40: =+G40*F40 -> #DIV/0! | K40: =+J40*I40 -> 0 | N40: =+M40*L40 -> 0 | Q40: =+P40*O40 -> 0 | T40: =+S40*R40 -> 0
E41: =D41*C41 -> 0 | F41: ='Proyeccion Ventas'!C10 -> 3 | G41: =$E$60 -> #DIV/0! | H41: =+G41*F41 -> #DIV/0! | K41: =+J41*I41 -> 0 | N41: =+M41*L41 -> 0 | Q41: =+P41*O41 -> 0 | T41: =+S41*R41 -> 0
E42: =D42*C42 -> 0 | F42: ='Proyeccion Ventas'!C11 -> 3 | G42: =$E$60 -> #DIV/0! | H42: =+G42*F42 -> #DIV/0! | K42: =+J42*I42 -> 0 | N42: =+M42*L42 -> 0 | Q42: =+P42*O42 -> 0 | T42: =+S42*R42 -> 0
E43: =D43*C43 -> 0 | F43: ='Proyeccion Ventas'!C12 -> 3 | G43: =$E$60 -> #DIV/0! | H43: =+G43*F43 -> #DIV/0! | K43: =+J43*I43 -> 0 | N43: =+M43*L43 -> 0 | Q43: =+P43*O43 -> 0 | T43: =+S43*R43 -> 0
E44: =D44*C44 -> 0 | F44: ='Proyeccion Ventas'!C13 -> 3 | G44: =$E$60 -> #DIV/0! | H44: =+G44*F44 -> #DIV/0! | K44: =+J44*I44 -> 0 | N44: =+M44*L44 -> 0 | Q44: =+P44*O44 -> 0 | T44: =+S44*R44 -> 0
E45: =D45*C45 -> 0 | F45: ='Proyeccion Ventas'!C14 -> 3 | G45: =$E$60 -> #DIV/0! | H45: =+G45*F45 -> #DIV/0! | K45: =+J45*I45 -> 0 | N45: =+M45*L45 -> 0 | Q45: =+P45*O45 -> 0 | T45: =+S45*R45 -> 0
E46: =D46*C46 -> 0 | F46: ='Proyeccion Ventas'!C15 -> 3 | G46: =$E$60 -> #DIV/0! | H46: =+G46*F46 -> #DIV/0! | K46: =+J46*I46 -> 0 | N46: =+M46*L46 -> 0 | Q46: =+P46*O46 -> 0 | T46: =+S46*R46 -> 0
E47: =D47*C47 -> 0 | F47: ='Proyeccion Ventas'!C16 -> 3 | G47: =$E$60 -> #DIV/0! | H47: =+G47*F47 -> #DIV/0! | K47: =+J47*I47 -> 0 | N47: =+M47*L47 -> 0 | Q47: =+P47*O47 -> 0 | T47: =+S47*R47 -> 0
E48: =D48*C48 -> 0 | H48: =+G48*F48 -> 0 | K48: =+J48*I48 -> 0 | N48: =+M48*L48 -> 0 | Q48: =+P48*O48 -> 0 | T48: =+S48*R48 -> 0
...

Sheet Costos Indirectos Fabricacion
A2: Costos indirectos de fabricación
A4: Concepto | B4: Mes 1 | C4: Mes 2 | D4: Mes 3 | E4: Mes 4 | F4: Mes 5 | G4: Mes 6 | H4: Mes 7 | I4: Mes 8 | J4: Mes 9 | K4: Mes 10 | L4: Mes 11 | M4: Mes 12 | N4: Año 1 | O4: Año 2 | P4: Año 3 | Q4: Año 4 | R4: Año 5
A5: Internet | N5: =+SUM(B5:M5) -> 0 | O5: =+N5*1.05 -> 0 | P5: =+O5*1.05 -> 0 | Q5: =+P5*1.05 -> 0 | R5: =+Q5*1.05 -> 0
A6: Electricidad | N6: =+SUM(B6:M6) -> 0 | O6: =+N6*1.05 -> 0 | P6: =+O6*1.05 -> 0 | Q6: =+P6*1.05 -> 0 | R6: =+Q6*1.05 -> 0
A7: Plataformas digitales | N7: =+SUM(B7:M7) -> 0 | O7: =+N7*1.05 -> 0 | P7: =+O7*1.05 -> 0 | Q7: =+P7*1.05 -> 0 | R7: =+Q7*1.05 -> 0
A8: Publicidad digital | N8: =+SUM(B8:M8) -> 0 | O8: =+N8*1.05 -> 0 | P8: =+O8*1.05 -> 0 | Q8: =+P8*1.05 -> 0 | R8: =+Q8*1.05 -> 0
N9: =+SUM(B9:M9) -> 0 | O9: =+N9*1.05 -> 0 | P9: =+O9*1.05 -> 0 | Q9: =+P9*1.05 -> 0 | R9: =+Q9*1.05 -> 0
N10: =+SUM(B10:M10) -> 0 | O10: =+N10*1.05 -> 0 | P10: =+O10*1.05 -> 0 | Q10: =+P10*1.05 -> 0 | R10: =+Q10*1.05 -> 0
N11: =+SUM(B11:M11) -> 0 | O11: =+N11*1.05 -> 0 | P11: =+O11*1.05 -> 0 | Q11: =+P11*1.05 -> 0 | R11: =+Q11*1.05 -> 0
N16: =+SUM(B16:M16) -> 0 | O16: =+N16*1.05 -> 0 | P16: =+O16*1.05 -> 0 | Q16: =+P16*1.05 -> 0 | R16: =+Q16*1.05 -> 0
N17: =+SUM(B17:M17) -> 0 | O17: =+N17*1.05 -> 0 | P17: =+O17*1.05 -> 0 | Q17: =+P17*1.05 -> 0 | R17: =+Q17*1.05 -> 0
N18: =+SUM(B18:M18) -> 0 | O18: =+N18*1.05 -> 0 | P18: =+O18*1.05 -> 0 | Q18: =+P18*1.05 -> 0 | R18: =+Q18*1.05 -> 0
N19: =+SUM(B19:M19) -> 0 | O19: =+N19*1.05 -> 0 | P19: =+O19*1.05 -> 0 | Q19: =+P19*1.05 -> 0 | R19: =+Q19*1.05 -> 0
A20: Total | B20: =SUM(B5:B19) -> 0 | N20: =+SUM(B20:M20) -> 0 | O20: =SUM(O5:O19) -> 0 | P20: =SUM(P5:P19) -> 0 | Q20: =SUM(Q5:Q19) -> 0 | R20: =SUM(R5:R19) -> 0

Sheet Ppto gastos fijos
A2: Gastos fijos mensuales
A4: Concepto | B4: Mes 1 | C4: Mes 2 | D4: Mes 3 | E4: Mes 4 | F4: Mes 5 | G4: Mes 6 | H4: Mes 7 | I4: Mes 8 | J4: Mes 9 | K4: Mes 10 | L4: Mes 11 | M4: Mes 12 | N4: Año 1 | O4: Año 2 | P4: Año 3 | Q4: Año 4 | R4: Año 5
A5: arrirndo | B5: 1000000 | N5: =+SUM(B5:M5) -> 1000000 | O5: =+N5*1.05 -> 1050000 | P5: =+O5*1.05 -> 1102500 | Q5: =+P5*1.05 -> 1157625 | R5: =+Q5*1.05 -> 1215506.2
A6: sservicios | B6: 200000 | N6: =+SUM(B6:M6) -> 200000 | O6: =+N6*1.05 -> 210000 | P6: =+O6*1.05 -> 220500 | Q6: =+P6*1.05 -> 231525 | R6: =+Q6*1.05 -> 243101.25
A7: gerente | B7: 3000000 | N7: =+SUM(B7:M7) -> 3000000 | O7: =+N7*1.05 -> 3150000 | P7: =+O7*1.05 -> 3307500 | Q7: =+P7*1.05 -> 3472875 | R7: =+Q7*1.05 -> 3646518.8
A8: ventas | B8: 3000000 | N8: =+SUM(B8:M8) -> 3000000 | O8: =+N8*1.05 -> 3150000 | P8: =+O8*1.05 -> 3307500 | Q8: =+P8*1.05 -> 3472875 | R8: =+Q8*1.05 -> 3646518.8
A9: atencion al cliente | B9: 3000000 | N9: =+SUM(B9:M9) -> 3000000 | O9: =+N9*1.05 -> 3150000 | P9: =+O9*1.05 -> 3307500 | Q9: =+P9*1.05 -> 3472875 | R9: =+Q9*1.05 -> 3646518.8
A10: Honorarios contador | B10: 400000 | N10: =+SUM(B10:M10) -> 400000 | O10: =+N10*1.05 -> 420000 | P10: =+O10*1.05 -> 441000 | Q10: =+P10*1.05 -> 463050 | R10: =+Q10*1.05 -> 486202.5
A11: internet | B11: 100000 | N11: =+SUM(B11:M11) -> 100000 | O11: =+N11*1.05 -> 105000 | P11: =+O11*1.05 -> 110250 | Q11: =+P11*1.05 -> 115762.5 | R11: =+Q11*1.05 -> 121550.62
N12: =+SUM(B12:M12) -> 0 | O12: =+N12*1.05 -> 0 | P12: =+O12*1.05 -> 0 | Q12: =+P12*1.05 -> 0 | R12: =+Q12*1.05 -> 0
N13: =+SUM(B13:M13) -> 0 | O13: =+N13*1.05 -> 0 | P13: =+O13*1.05 -> 0 | Q13: =+P13*1.05 -> 0 | R13: =+Q13*1.05 -> 0
N14: =+SUM(B14:M14) -> 0 | O14: =+N14*1.05 -> 0 | P14: =+O14*1.05 -> 0 | Q14: =+P14*1.05 -> 0 | R14: =+Q14*1.05 -> 0
N15: =+SUM(B15:M15) -> 0 | O15: =+N15*1.05 -> 0 | P15: =+O15*1.05 -> 0 | Q15: =+P15*1.05 -> 0 | R15: =+Q15*1.05 -> 0
N16: =+SUM(B16:M16) -> 0 | O16: =+N16*1.05 -> 0 | P16: =+O16*1.05 -> 0 | Q16: =+P16*1.05 -> 0 | R16: =+Q16*1.05 -> 0
N17: =+SUM(B17:M17) -> 0 | O17: =+N17*1.05 -> 0 | P17: =+O17*1.05 -> 0 | Q17: =+P17*1.05 -> 0 | R17: =+Q17*1.05 -> 0
N18: =+SUM(B18:M18) -> 0 | O18: =+N18*1.05 -> 0 | P18: =+O18*1.05 -> 0 | Q18: =+P18*1.05 -> 0 | R18: =+Q18*1.05 -> 0
N19: =+SUM(B19:M19) -> 0 | O19: =+N19*1.05 -> 0 | P19: =+O19*1.05 -> 0 | Q19: =+P19*1.05 -> 0 | R19: =+Q19*1.05 -> 0
N20: =+SUM(B20:M20) -> 0 | O20: =+N20*1.05 -> 0 | P20: =+O20*1.05 -> 0 | Q20: =+P20*1.05 -> 0 | R20: =+Q20*1.05 -> 0
N21: =+SUM(B21:M21) -> 0 | O21: =+N21*1.05 -> 0 | P21: =+O21*1.05 -> 0 | Q21: =+P21*1.05 -> 0 | R21: =+Q21*1.05 -> 0
N22: =+SUM(B22:M22) -> 0 | O22: =+N22*1.05 -> 0 | P22: =+O22*1.05 -> 0 | Q22: =+P22*1.05 -> 0 | R22: =+Q22*1.05 -> 0
N23: =+SUM(B23:M23) -> 0 | O23: =+N23*1.05 -> 0 | P23: =+O23*1.05 -> 0 | Q23: =+P23*1.05 -> 0 | R23: =+Q23*1.05 -> 0
A24: Total | B24: =SUM(B5:B23) -> 10700000 | N24: =+SUM(B24:M24) -> 10700000 | O24: =SUM(O5:O23) -> 11235000 | P24: =SUM(P5:P23) -> 11796750 | Q24: =SUM(Q5:Q23) -> 12386588 | R24: =SUM(R5:R23) -> 13005917
N28: Año 1 | O28: Año 2 | P28: Año 3 | Q28: Año 4 | R28: Año 5
N38: =SUM(N20:N37) -> 10700000 | O38: =SUM(O20:O37) -> 11235000 | P38: =SUM(P20:P37) -> 11796750 | Q38: =SUM(Q20:Q37) -> 12386588 | R38: =SUM(R20:R37) -> 13005917

Sheet Ppto gastos variables
A2: Gastos variables mensuales
A4: Concepto | B4: Mensual
A5: Publicidad | B5: 500000
A6: Tarjetas de presentación
A7: Volantes
A8: Pagina web
A9: Transporte
A21: Total | B21: =SUM(B5:B20) -> 500000

Sheet Infraestructura
A1: Inversiones
B4: Año 1 | E4: Año 2 | H4: Año 3 | K4: Año 4 | N4: Año 5
A5: Descripción | B5: Cantidad | C5: Valor Unitario | D5: Valor Total | E5: Cantidad | F5: Valor Unitario | G5: Valor Total | H5: Cantidad | I5: Valor Unitario | J5: Valor Total | K5: Cantidad | L5: Valor Unitario | M5: Valor Total | N5: Cantidad | O5: Valor Unitario | P5: Valor Total
A6: Construcciones y edificios
D7: =+C7*B7 -> 0 | G7: =+F7*E7 -> 0 | J7: =+I7*H7 -> 0 | M7: =+L7*K7 -> 0 | P7: =+O7*N7 -> 0
D8: =+C8*B8 -> 0 | G8: =+F8*E8 -> 0 | J8: =+I8*H8 -> 0 | M8: =+L8*K8 -> 0 | P8: =+O8*N8 -> 0
D9: =+C9*B9 -> 0 | G9: =+F9*E9 -> 0 | J9: =+I9*H9 -> 0 | M9: =+L9*K9 -> 0 | P9: =+O9*N9 -> 0
D10: =+C10*B10 -> 0 | G10: =+F10*E10 -> 0 | J10: =+I10*H10 -> 0 | M10: =+L10*K10 -> 0 | P10: =+O10*N10 -> 0
D11: =+C11*B11 -> 0 | G11: =+F11*E11 -> 0 | J11: =+I11*H11 -> 0 | M11: =+L11*K11 -> 0 | P11: =+O11*N11 -> 0
D12: =+C12*B12 -> 0 | G12: =+F12*E12 -> 0 | J12: =+I12*H12 -> 0 | M12: =+L12*K12 -> 0 | P12: =+O12*N12 -> 0
D13: =+C13*B13 -> 0 | G13: =+F13*E13 -> 0 | J13: =+I13*H13 -> 0 | M13: =+L13*K13 -> 0 | P13: =+O13*N13 -> 0
D14: =+C14*B14 -> 0 | G14: =+F14*E14 -> 0 | J14: =+I14*H14 -> 0 | M14: =+L14*K14 -> 0 | P14: =+O14*N14 -> 0
A15: Total | D15: =+SUM(D7:D14) -> 0 | G15: =+SUM(G7:G14) -> 0 | J15: =+SUM(J7:J14) -> 0 | M15: =+SUM(M7:M14) -> 0 | P15: =+SUM(P7:P14) -> 0
A17: Maquinaria y Equipo
A18: Portátil | B18: 4 | C18: 2000000 | D18: =+C18*B18 -> 8000000 | G18: =+F18*E18 -> 0 | J18: =+I18*H18 -> 0 | M18: =+L18*K18 -> 0 | P18: =+O18*N18 -> 0
A19: Celular) | B19: 4 | C19: 1000000 | D19: =+C19*B19 -> 4000000 | G19: =+F19*E19 -> 0 | J19: =+I19*H19 -> 0 | M19: =+L19*K19 -> 0 | P19: =+O19*N19 -> 0
A20: Batería portátil | B20: 4 | C20: 180000 | D20: =+C20*B20 -> 720000 | G20: =+F20*E20 -> 0 | J20: =+I20*H20 -> 0 | M20: =+L20*K20 -> 0 | P20: =+O20*N20 -> 0
D21: =+C21*B21 -> 0 | G21: =+F21*E21 -> 0 | J21: =+I21*H21 -> 0 | M21: =+L21*K21 -> 0 | P21: =+O21*N21 -> 0
D22: =+C22*B22 -> 0 | G22: =+F22*E22 -> 0 | J22: =+I22*H22 -> 0 | M22: =+L22*K22 -> 0 | P22: =+O22*N22 -> 0
D23: =+C23*B23 -> 0 | G23: =+F23*E23 -> 0 | J23: =+I23*H23 -> 0 | M23: =+L23*K23 -> 0 | P23: =+O23*N23 -> 0
D24: =+C24*B24 -> 0 | G24: =+F24*E24 -> 0 | J24: =+I24*H24 -> 0 | M24: =+L24*K24 -> 0 | P24: =+O24*N24 -> 0
D25: =+C25*B25 -> 0 | G25: =+F25*E25 -> 0 | J25: =+I25*H25 -> 0 | M25: =+L25*K25 -> 0 | P25: =+O25*N25 -> 0
D26: =+C26*B26 -> 0 | G26: =+F26*E26 -> 0 | J26: =+I26*H26 -> 0 | M26: =+L26*K26 -> 0 | P26: =+O26*N26 -> 0
D27: =+C27*B27 -> 0 | G27: =+F27*E27 -> 0 | J27: =+I27*H27 -> 0 | M27: =+L27*K27 -> 0 | P27: =+O27*N27 -> 0
D28: =+C28*B28 -> 0 | G28: =+F28*E28 -> 0 | J28: =+I28*H28 -> 0 | M28: =+L28*K28 -> 0 | P28: =+O28*N28 -> 0
D29: =+C29*B29 -> 0 | G29: =+F29*E29 -> 0 | J29: =+I29*H29 -> 0 | M29: =+L29*K29 -> 0 | P29: =+O29*N29 -> 0
D30: =+C30*B30 -> 0 | G30: =+F30*E30 -> 0 | J30: =+I30*H30 -> 0 | M30: =+L30*K30 -> 0 | P30: =+O30*N30 -> 0
D31: =+C31*B31 -> 0 | G31: =+F31*E31 -> 0 | J31: =+I31*H31 -> 0 | M31: =+L31*K31 -> 0 | P31: =+O31*N31 -> 0
D32: =+C32*B32 -> 0 | G32: =+F32*E32 -> 0 | J32: =+I32*H32 -> 0 | M32: =+L32*K32 -> 0 | P32: =+O32*N32 -> 0
... D38: =+C38*B38 -> 0 | G38: =+F38*E38 -> 0 | J38: =+I38*H38 -> 0 | M38: =+L38*K38 -> 0 | P38: =+O38*N38 -> 0
A39: Total | D39: =+SUM(D18:D38) -> 12720000 | G39: =+SUM(G18:G38) -> 0 | J39: =+SUM(J18:J38) -> 0 | M39: =+SUM(M18:M38) -> 0 | P39: =+SUM(P18:P38) -> 0
A41: Muebles y Enseres
A42: Silla | B42: 4 | C42: 300000 | D42: =+C42*B42 -> 1200000 | G42: =+F42*E42 -> 0 | J42: =+I42*H42 -> 0 | M42: =+L42*K42 -> 0 | P42: =+O42*N42 -> 0
A43: Escritorio | B43: 4 | C43: 500000 | D43: =+C43*B43 -> 2000000 | G43: =+F43*E43 -> 0 | J43: =+I43*H43 -> 0 | M43: =+L43*K43 -> 0 | P43: =+O43*N43 -> 0
A44: Tablero | B44: 4 | C44: 80000 | D44: =+C44*B44 -> 320000 | G44: =+F44*E44 -> 0 | J44: =+I44*H44 -> 0 | M44: =+L44*K44 -> 0 | P44: =+O44*N44 -> 0
D45: =+C45*B45 -> 0 | G45: =+F45*E45 -> 0 | J45: =+I45*H45 -> 0 | M45: =+L45*K45 -> 0 | P45: =+O45*N45 -> 0
D46: =+C46*B46 -> 0 | G46: =+F46*E46 -> 0 | J46: =+I46*H46 -> 0 | M46: =+L46*K46 -> 0 | P46: =+O46*N46 -> 0
D47: =+C47*B47 -> 0 | G47: =+F47*E47 -> 0 | J47: =+I47*H47 -> 0 | M47: =+L47*K47 -> 0 | P47: =+O47*N47 -> 0
A48: Total | D48: =+SUM(D42:D47) -> 3520000 | G48: =+SUM(G42:G47) -> 0 | J48: =+SUM(J42:J47) -> 0 | M48: =+SUM(M42:M47) -> 0 | P48: =+SUM(P42:P47) -> 0
A50: Equipos de Transporte
...

Sheet Punto de equilibrio
B2: Producto 1 | C2: Producto 2 | D2: Producto 3 | E2: Producto 4 | F2: Producto 5
A3: Gastos fijos mensuales | B3: ='Ppto gastos fijos'!B24+'Ppto gastos variables'!B21+'Costos Indirectos Fabricacion'!B20 -> 11200000 | C3: ='Ppto gastos fijos'!B24+'Ppto gastos variables'!B21+'Costos Indirectos Fabricacion'!B20 -> 11200000
A4: Precio Venta | B4: ='Proyeccion Ventas'!I5 -> 40000 | C4: ='Proyeccion Ventas'!J5 -> 70000
A5: Costo unitario | B5: ='Costos Unitarios de producción'!E28 -> 6310 | C5: ='Costos Unitarios de producción'!E60 -> #DIV/0!
A6: Margen contribución | B6: =+B4-B5 -> 33690 | C6: =+C4-C5 -> #DIV/0! | D6: =+D4-D5 -> 0 | E6: =+E4-E5 -> 0 | F6: =+F4-F5 -> 0
A7: Punto de equilibrio | B7: =+B3/B6 -> 332.44286 | C7: =+C3/C6 -> #DIV/0! | D7: =+D3/D6 -> #DIV/0! | E7: =+E3/E6 -> #DIV/0! | F7: =+F3/F6 -> #DIV/0!
